Exception happened during processing of request from ('127.0.0.1', 33260)
Traceback (most recent call last):
  File "/usr/lib/python2.7/SocketServer.py", line 582, in process_request_thread
    self.finish_request(request, client_address)
  File "/usr/lib/python2.7/SocketServer.py", line 323, in finish_request
    self.RequestHandlerClass(request, client_address, self)
  File "/usr/lib/python2.7/SocketServer.py", line 638, in __init__
    self.handle()
  File "rfc_1928.py", line 228, in handle
    self.handle_socks5(recv)
  File "rfc_1928.py", line 259, in handle_socks5
    self.request.getpeername())
  File "rfc_1928.py", line 159, in socksv5_get_remote
    remote, raddr, rport = sshsocket(dest,src)
  File "rfc_1928.py", line 195, in sshsocket
    remote=sshtunnel.getSocket(dest, src)
  File "rfc_1928.py", line 137, in getSocket
    res=trans.open_channel('direct-tcpip',dest,src)
  File "/usr/local/lib/python2.7/dist-packages/paramiko/transport.py", line 731, in open_channel
    raise SSHException('SSH session not active')
SSHException: SSH session not active
----------------------------------------
(4, 4, 1404226308.992907, 4, u'www.google.com')
----------------------------------------
Exception happened during processing of request from ('127.0.0.1', 33261)
Traceback (most recent call last):
  File "/usr/lib/python2.7/SocketServer.py", line 582, in process_request_thread
    self.finish_request(request, client_address)
  File "/usr/lib/python2.7/SocketServer.py", line 323, in finish_request
    self.RequestHandlerClass(request, client_address, self)
  File "/usr/lib/python2.7/SocketServer.py", line 638, in __init__
    self.handle()
  File "rfc_1928.py", line 228, in handle
    self.handle_socks5(recv)
  File "rfc_1928.py", line 259, in handle_socks5
    self.request.getpeername())
  File "rfc_1928.py", line 159, in socksv5_get_remote
    remote, raddr, rport = sshsocket(dest,src)
  File "rfc_1928.py", line 195, in sshsocket
    remote=sshtunnel.getSocket(dest, src)
  File "rfc_1928.py", line 137, in getSocket
    res=trans.open_channel('direct-tcpip',dest,src)
  File "/usr/local/lib/python2.7/dist-packages/paramiko/transport.py", line 731, in open_channel
    raise SSHException('SSH session not active')
SSHException: SSH session not active

----------------------------------------
Exception happened during processing of request from ('127.0.0.1', 51742)
Traceback (most recent call last):
  File "/usr/lib/python2.7/SocketServer.py", line 582, in process_request_thread
    self.finish_request(request, client_address)
  File "/usr/lib/python2.7/SocketServer.py", line 323, in finish_request
    self.RequestHandlerClass(request, client_address, self)
  File "/usr/lib/python2.7/SocketServer.py", line 638, in __init__
    self.handle()
  File "/home/xxc/文档/workspace/sshtunnel/rfc_1928.py", line 228, in handle
    self.handle_socks5(recv)
  File "/home/xxc/文档/workspace/sshtunnel/rfc_1928.py", line 259, in handle_socks5
    sp_remote,rtype,raddr,rport ,handle= \
  File "/home/xxc/文档/workspace/sshtunnel/rfc_1928.py", line 159, in socksv5_get_remote
    remote, raddr, rport = sshsocket(dest,src)
  File "/home/xxc/文档/workspace/sshtunnel/rfc_1928.py", line 195, in sshsocket
    remote=sshtunnel.getSocket(dest, src)
  File "/home/xxc/文档/workspace/sshtunnel/rfc_1928.py", line 137, in getSocket
    res=trans.open_channel('direct-tcpip',dest,src)
  File "/usr/local/lib/python2.7/dist-packages/paramiko/transport.py", line 773, in open_channel
    raise e
ChannelException: Connect failed
----------------------------------------
超时重试 2
add clients1.google.com
主机不可达
----------------------------------------
Exception happened during processing of request from ('127.0.0.1', 51747)
Traceback (most recent call last):
  File "/usr/lib/python2.7/SocketServer.py", line 582, in process_request_thread
    self.finish_request(request, client_address)
  File "/usr/lib/python2.7/SocketServer.py", line 323, in finish_request
    self.RequestHandlerClass(request, client_address, self)
  File "/usr/lib/python2.7/SocketServer.py", line 638, in __init__
    self.handle()
  File "/home/xxc/文档/workspace/sshtunnel/rfc_1928.py", line 228, in handle
    self.handle_socks5(recv)
  File "/home/xxc/文档/workspace/sshtunnel/rfc_1928.py", line 259, in handle_socks5
    sp_remote,rtype,raddr,rport ,handle= \
  File "/home/xxc/文档/workspace/sshtunnel/rfc_1928.py", line 159, in socksv5_get_remote
    remote, raddr, rport = sshsocket(dest,src)
  File "/home/xxc/文档/workspace/sshtunnel/rfc_1928.py", line 195, in sshsocket
    remote=sshtunnel.getSocket(dest, src)
  File "/home/xxc/文档/workspace/sshtunnel/rfc_1928.py", line 137, in getSocket
    res=trans.open_channel('direct-tcpip',dest,src)
  File "/usr/local/lib/python2.7/dist-packages/paramiko/transport.py", line 773, in open_channel
    raise e
ChannelException: Connect failed

